2022-12-05 08:57:51,117 -  * Running on http://127.0.0.1:5000/ (Press CTRL+C to quit)
2022-12-05 08:57:52,607 - Converting docker
2022-12-05 08:57:52,634 - 127.0.0.1 - - [05/Dec/2022 08:57:52] "[37mGET /convert?filename=docker HTTP/1.1[0m" 200 -
2022-12-05 09:07:51,182 -  * Running on http://127.0.0.1:5000/ (Press CTRL+C to quit)
2022-12-05 09:07:52,696 - Converting docker
2022-12-05 09:07:52,790 - 127.0.0.1 - - [05/Dec/2022 09:07:52] "[37mGET /convert?filename=docker HTTP/1.1[0m" 200 -
2022-12-05 09:08:29,146 -  * Running on http://127.0.0.1:5000/ (Press CTRL+C to quit)
2022-12-05 09:08:31,395 - Exception on /convert [GET]
Traceback (most recent call last):
  File "C:\Users\eitan\AppData\Local\Packages\PythonSoftwareFoundation.Python.3.9_qbz5n2kfra8p0\LocalCache\local-packages\Python39\site-packages\flask\app.py", line 2447, in wsgi_app
    response = self.full_dispatch_request()
  File "C:\Users\eitan\AppData\Local\Packages\PythonSoftwareFoundation.Python.3.9_qbz5n2kfra8p0\LocalCache\local-packages\Python39\site-packages\flask\app.py", line 1952, in full_dispatch_request
    rv = self.handle_user_exception(e)
  File "C:\Users\eitan\AppData\Local\Packages\PythonSoftwareFoundation.Python.3.9_qbz5n2kfra8p0\LocalCache\local-packages\Python39\site-packages\flask\app.py", line 1821, in handle_user_exception
    reraise(exc_type, exc_value, tb)
  File "C:\Users\eitan\AppData\Local\Packages\PythonSoftwareFoundation.Python.3.9_qbz5n2kfra8p0\LocalCache\local-packages\Python39\site-packages\flask\_compat.py", line 39, in reraise
    raise value
  File "C:\Users\eitan\AppData\Local\Packages\PythonSoftwareFoundation.Python.3.9_qbz5n2kfra8p0\LocalCache\local-packages\Python39\site-packages\flask\app.py", line 1950, in full_dispatch_request
    rv = self.dispatch_request()
  File "C:\Users\eitan\AppData\Local\Packages\PythonSoftwareFoundation.Python.3.9_qbz5n2kfra8p0\LocalCache\local-packages\Python39\site-packages\flask\app.py", line 1936, in dispatch_request
    return self.view_functions[rule.endpoint](**req.view_args)
  File "c:\Users\eitan\projects\img2pdf\main.py", line 11, in hello_world
    return convert(filename)
  File "c:\Users\eitan\projects\img2pdf\lib\utils.py", line 10, in convert
    print (confdata.jpgPath)
AttributeError: 'dict' object has no attribute 'jpgPath'
2022-12-05 09:08:31,445 - 127.0.0.1 - - [05/Dec/2022 09:08:31] "[35m[1mGET /convert?filename=docker HTTP/1.1[0m" 500 -
2022-12-05 09:18:39,251 -  * Running on http://127.0.0.1:5000/ (Press CTRL+C to quit)
2022-12-05 09:18:41,863 - Converting docker
2022-12-05 09:18:41,926 - 127.0.0.1 - - [05/Dec/2022 09:18:41] "[37mGET /convert?filename=docker HTTP/1.1[0m" 200 -
2022-12-05 09:19:55,431 -  * Running on http://127.0.0.1:5000/ (Press CTRL+C to quit)
2022-12-05 09:19:57,725 - Converting docker
2022-12-05 09:19:57,726 - Exception on /convert [GET]
Traceback (most recent call last):
  File "C:\Users\eitan\AppData\Local\Packages\PythonSoftwareFoundation.Python.3.9_qbz5n2kfra8p0\LocalCache\local-packages\Python39\site-packages\flask\app.py", line 2447, in wsgi_app
    response = self.full_dispatch_request()
  File "C:\Users\eitan\AppData\Local\Packages\PythonSoftwareFoundation.Python.3.9_qbz5n2kfra8p0\LocalCache\local-packages\Python39\site-packages\flask\app.py", line 1952, in full_dispatch_request
    rv = self.handle_user_exception(e)
  File "C:\Users\eitan\AppData\Local\Packages\PythonSoftwareFoundation.Python.3.9_qbz5n2kfra8p0\LocalCache\local-packages\Python39\site-packages\flask\app.py", line 1821, in handle_user_exception
    reraise(exc_type, exc_value, tb)
  File "C:\Users\eitan\AppData\Local\Packages\PythonSoftwareFoundation.Python.3.9_qbz5n2kfra8p0\LocalCache\local-packages\Python39\site-packages\flask\_compat.py", line 39, in reraise
    raise value
  File "C:\Users\eitan\AppData\Local\Packages\PythonSoftwareFoundation.Python.3.9_qbz5n2kfra8p0\LocalCache\local-packages\Python39\site-packages\flask\app.py", line 1950, in full_dispatch_request
    rv = self.dispatch_request()
  File "C:\Users\eitan\AppData\Local\Packages\PythonSoftwareFoundation.Python.3.9_qbz5n2kfra8p0\LocalCache\local-packages\Python39\site-packages\flask\app.py", line 1936, in dispatch_request
    return self.view_functions[rule.endpoint](**req.view_args)
  File "c:\Users\eitan\projects\img2pdf\main.py", line 11, in hello_world
    return convert(filename)
  File "c:\Users\eitan\projects\img2pdf\lib\utils.py", line 14, in convert
    image = Image.open(img_path)
  File "C:\Users\eitan\AppData\Local\Packages\PythonSoftwareFoundation.Python.3.9_qbz5n2kfra8p0\LocalCache\local-packages\Python39\site-packages\PIL\Image.py", line 3131, in open
    fp = builtins.open(filename, "rb")
FileNotFoundError: [Errno 2] No such file or directory: 'c:\\Users\\eitan\\projects\\img2pdfdocker.jpg'
2022-12-05 09:19:57,744 - 127.0.0.1 - - [05/Dec/2022 09:19:57] "[35m[1mGET /convert?filename=docker HTTP/1.1[0m" 500 -
2022-12-05 09:20:00,364 - Converting docker
2022-12-05 09:20:00,364 - Exception on /convert [GET]
Traceback (most recent call last):
  File "C:\Users\eitan\AppData\Local\Packages\PythonSoftwareFoundation.Python.3.9_qbz5n2kfra8p0\LocalCache\local-packages\Python39\site-packages\flask\app.py", line 2447, in wsgi_app
    response = self.full_dispatch_request()
  File "C:\Users\eitan\AppData\Local\Packages\PythonSoftwareFoundation.Python.3.9_qbz5n2kfra8p0\LocalCache\local-packages\Python39\site-packages\flask\app.py", line 1952, in full_dispatch_request
    rv = self.handle_user_exception(e)
  File "C:\Users\eitan\AppData\Local\Packages\PythonSoftwareFoundation.Python.3.9_qbz5n2kfra8p0\LocalCache\local-packages\Python39\site-packages\flask\app.py", line 1821, in handle_user_exception
    reraise(exc_type, exc_value, tb)
  File "C:\Users\eitan\AppData\Local\Packages\PythonSoftwareFoundation.Python.3.9_qbz5n2kfra8p0\LocalCache\local-packages\Python39\site-packages\flask\_compat.py", line 39, in reraise
    raise value
  File "C:\Users\eitan\AppData\Local\Packages\PythonSoftwareFoundation.Python.3.9_qbz5n2kfra8p0\LocalCache\local-packages\Python39\site-packages\flask\app.py", line 1950, in full_dispatch_request
    rv = self.dispatch_request()
  File "C:\Users\eitan\AppData\Local\Packages\PythonSoftwareFoundation.Python.3.9_qbz5n2kfra8p0\LocalCache\local-packages\Python39\site-packages\flask\app.py", line 1936, in dispatch_request
    return self.view_functions[rule.endpoint](**req.view_args)
  File "c:\Users\eitan\projects\img2pdf\main.py", line 11, in hello_world
    return convert(filename)
  File "c:\Users\eitan\projects\img2pdf\lib\utils.py", line 14, in convert
    image = Image.open(img_path)
  File "C:\Users\eitan\AppData\Local\Packages\PythonSoftwareFoundation.Python.3.9_qbz5n2kfra8p0\LocalCache\local-packages\Python39\site-packages\PIL\Image.py", line 3131, in open
    fp = builtins.open(filename, "rb")
FileNotFoundError: [Errno 2] No such file or directory: 'c:\\Users\\eitan\\projects\\img2pdfdocker.jpg'
2022-12-05 09:20:00,364 - 127.0.0.1 - - [05/Dec/2022 09:20:00] "[35m[1mGET /convert?filename=docker HTTP/1.1[0m" 500 -
2022-12-05 09:20:17,569 -  * Running on http://127.0.0.1:5000/ (Press CTRL+C to quit)
2022-12-05 09:20:43,556 - Converting docker
2022-12-05 09:20:43,556 - Exception on /convert [GET]
Traceback (most recent call last):
  File "C:\Users\eitan\AppData\Local\Packages\PythonSoftwareFoundation.Python.3.9_qbz5n2kfra8p0\LocalCache\local-packages\Python39\site-packages\flask\app.py", line 2447, in wsgi_app
    response = self.full_dispatch_request()
  File "C:\Users\eitan\AppData\Local\Packages\PythonSoftwareFoundation.Python.3.9_qbz5n2kfra8p0\LocalCache\local-packages\Python39\site-packages\flask\app.py", line 1952, in full_dispatch_request
    rv = self.handle_user_exception(e)
  File "C:\Users\eitan\AppData\Local\Packages\PythonSoftwareFoundation.Python.3.9_qbz5n2kfra8p0\LocalCache\local-packages\Python39\site-packages\flask\app.py", line 1821, in handle_user_exception
    reraise(exc_type, exc_value, tb)
  File "C:\Users\eitan\AppData\Local\Packages\PythonSoftwareFoundation.Python.3.9_qbz5n2kfra8p0\LocalCache\local-packages\Python39\site-packages\flask\_compat.py", line 39, in reraise
    raise value
  File "C:\Users\eitan\AppData\Local\Packages\PythonSoftwareFoundation.Python.3.9_qbz5n2kfra8p0\LocalCache\local-packages\Python39\site-packages\flask\app.py", line 1950, in full_dispatch_request
    rv = self.dispatch_request()
  File "C:\Users\eitan\AppData\Local\Packages\PythonSoftwareFoundation.Python.3.9_qbz5n2kfra8p0\LocalCache\local-packages\Python39\site-packages\flask\app.py", line 1936, in dispatch_request
    return self.view_functions[rule.endpoint](**req.view_args)
  File "c:\Users\eitan\projects\img2pdf\main.py", line 11, in hello_world
    return convert(filename)
  File "c:\Users\eitan\projects\img2pdf\lib\utils.py", line 14, in convert
    image = Image.open(img_path)
  File "C:\Users\eitan\AppData\Local\Packages\PythonSoftwareFoundation.Python.3.9_qbz5n2kfra8p0\LocalCache\local-packages\Python39\site-packages\PIL\Image.py", line 3131, in open
    fp = builtins.open(filename, "rb")
FileNotFoundError: [Errno 2] No such file or directory: 'c:\\Users\\eitan\\projects\\img2pdfdocker.jpg'
2022-12-05 09:20:43,556 - 127.0.0.1 - - [05/Dec/2022 09:20:43] "[35m[1mGET /convert?filename=docker HTTP/1.1[0m" 500 -
2022-12-05 09:20:58,700 -  * Running on http://127.0.0.1:5000/ (Press CTRL+C to quit)
2022-12-05 09:21:05,575 - Converting docker
2022-12-05 09:21:05,575 - Exception on /convert [GET]
Traceback (most recent call last):
  File "C:\Users\eitan\AppData\Local\Packages\PythonSoftwareFoundation.Python.3.9_qbz5n2kfra8p0\LocalCache\local-packages\Python39\site-packages\flask\app.py", line 2447, in wsgi_app
    response = self.full_dispatch_request()
  File "C:\Users\eitan\AppData\Local\Packages\PythonSoftwareFoundation.Python.3.9_qbz5n2kfra8p0\LocalCache\local-packages\Python39\site-packages\flask\app.py", line 1952, in full_dispatch_request
    rv = self.handle_user_exception(e)
  File "C:\Users\eitan\AppData\Local\Packages\PythonSoftwareFoundation.Python.3.9_qbz5n2kfra8p0\LocalCache\local-packages\Python39\site-packages\flask\app.py", line 1821, in handle_user_exception
    reraise(exc_type, exc_value, tb)
  File "C:\Users\eitan\AppData\Local\Packages\PythonSoftwareFoundation.Python.3.9_qbz5n2kfra8p0\LocalCache\local-packages\Python39\site-packages\flask\_compat.py", line 39, in reraise
    raise value
  File "C:\Users\eitan\AppData\Local\Packages\PythonSoftwareFoundation.Python.3.9_qbz5n2kfra8p0\LocalCache\local-packages\Python39\site-packages\flask\app.py", line 1950, in full_dispatch_request
    rv = self.dispatch_request()
  File "C:\Users\eitan\AppData\Local\Packages\PythonSoftwareFoundation.Python.3.9_qbz5n2kfra8p0\LocalCache\local-packages\Python39\site-packages\flask\app.py", line 1936, in dispatch_request
    return self.view_functions[rule.endpoint](**req.view_args)
  File "c:\Users\eitan\projects\img2pdf\main.py", line 11, in hello_world
    return convert(filename)
  File "c:\Users\eitan\projects\img2pdf\lib\utils.py", line 14, in convert
    image = Image.open(img_path)
  File "C:\Users\eitan\AppData\Local\Packages\PythonSoftwareFoundation.Python.3.9_qbz5n2kfra8p0\LocalCache\local-packages\Python39\site-packages\PIL\Image.py", line 3131, in open
    fp = builtins.open(filename, "rb")
FileNotFoundError: [Errno 2] No such file or directory: 'c:\\Users\\eitan\\projects\\img2pdfdocker.jpg'
2022-12-05 09:21:05,578 - 127.0.0.1 - - [05/Dec/2022 09:21:05] "[35m[1mGET /convert?filename=docker HTTP/1.1[0m" 500 -
2022-12-05 09:21:48,127 -  * Running on http://127.0.0.1:5000/ (Press CTRL+C to quit)
2022-12-05 09:21:51,073 - Converting docker
2022-12-05 09:21:51,074 - Exception on /convert [GET]
Traceback (most recent call last):
  File "C:\Users\eitan\AppData\Local\Packages\PythonSoftwareFoundation.Python.3.9_qbz5n2kfra8p0\LocalCache\local-packages\Python39\site-packages\flask\app.py", line 2447, in wsgi_app
    response = self.full_dispatch_request()
  File "C:\Users\eitan\AppData\Local\Packages\PythonSoftwareFoundation.Python.3.9_qbz5n2kfra8p0\LocalCache\local-packages\Python39\site-packages\flask\app.py", line 1952, in full_dispatch_request
    rv = self.handle_user_exception(e)
  File "C:\Users\eitan\AppData\Local\Packages\PythonSoftwareFoundation.Python.3.9_qbz5n2kfra8p0\LocalCache\local-packages\Python39\site-packages\flask\app.py", line 1821, in handle_user_exception
    reraise(exc_type, exc_value, tb)
  File "C:\Users\eitan\AppData\Local\Packages\PythonSoftwareFoundation.Python.3.9_qbz5n2kfra8p0\LocalCache\local-packages\Python39\site-packages\flask\_compat.py", line 39, in reraise
    raise value
  File "C:\Users\eitan\AppData\Local\Packages\PythonSoftwareFoundation.Python.3.9_qbz5n2kfra8p0\LocalCache\local-packages\Python39\site-packages\flask\app.py", line 1950, in full_dispatch_request
    rv = self.dispatch_request()
  File "C:\Users\eitan\AppData\Local\Packages\PythonSoftwareFoundation.Python.3.9_qbz5n2kfra8p0\LocalCache\local-packages\Python39\site-packages\flask\app.py", line 1936, in dispatch_request
    return self.view_functions[rule.endpoint](**req.view_args)
  File "c:\Users\eitan\projects\img2pdf\main.py", line 11, in hello_world
    return convert(filename)
  File "c:\Users\eitan\projects\img2pdf\lib\utils.py", line 14, in convert
    image = Image.open(img_path)
  File "C:\Users\eitan\AppData\Local\Packages\PythonSoftwareFoundation.Python.3.9_qbz5n2kfra8p0\LocalCache\local-packages\Python39\site-packages\PIL\Image.py", line 3131, in open
    fp = builtins.open(filename, "rb")
FileNotFoundError: [Errno 2] No such file or directory: 'c:\\Users\\eitan\\projects\\img2pdfdocker.jpg'
2022-12-05 09:21:51,078 - 127.0.0.1 - - [05/Dec/2022 09:21:51] "[35m[1mGET /convert?filename=docker HTTP/1.1[0m" 500 -
2022-12-05 09:22:01,524 - Converting docker
2022-12-05 09:22:01,525 - Exception on /convert [GET]
Traceback (most recent call last):
  File "C:\Users\eitan\AppData\Local\Packages\PythonSoftwareFoundation.Python.3.9_qbz5n2kfra8p0\LocalCache\local-packages\Python39\site-packages\flask\app.py", line 2447, in wsgi_app
    response = self.full_dispatch_request()
  File "C:\Users\eitan\AppData\Local\Packages\PythonSoftwareFoundation.Python.3.9_qbz5n2kfra8p0\LocalCache\local-packages\Python39\site-packages\flask\app.py", line 1952, in full_dispatch_request
    rv = self.handle_user_exception(e)
  File "C:\Users\eitan\AppData\Local\Packages\PythonSoftwareFoundation.Python.3.9_qbz5n2kfra8p0\LocalCache\local-packages\Python39\site-packages\flask\app.py", line 1821, in handle_user_exception
    reraise(exc_type, exc_value, tb)
  File "C:\Users\eitan\AppData\Local\Packages\PythonSoftwareFoundation.Python.3.9_qbz5n2kfra8p0\LocalCache\local-packages\Python39\site-packages\flask\_compat.py", line 39, in reraise
    raise value
  File "C:\Users\eitan\AppData\Local\Packages\PythonSoftwareFoundation.Python.3.9_qbz5n2kfra8p0\LocalCache\local-packages\Python39\site-packages\flask\app.py", line 1950, in full_dispatch_request
    rv = self.dispatch_request()
  File "C:\Users\eitan\AppData\Local\Packages\PythonSoftwareFoundation.Python.3.9_qbz5n2kfra8p0\LocalCache\local-packages\Python39\site-packages\flask\app.py", line 1936, in dispatch_request
    return self.view_functions[rule.endpoint](**req.view_args)
  File "c:\Users\eitan\projects\img2pdf\main.py", line 11, in hello_world
    return convert(filename)
  File "c:\Users\eitan\projects\img2pdf\lib\utils.py", line 14, in convert
    image = Image.open(img_path)
  File "C:\Users\eitan\AppData\Local\Packages\PythonSoftwareFoundation.Python.3.9_qbz5n2kfra8p0\LocalCache\local-packages\Python39\site-packages\PIL\Image.py", line 3131, in open
    fp = builtins.open(filename, "rb")
FileNotFoundError: [Errno 2] No such file or directory: 'c:\\Users\\eitan\\projects\\img2pdfdocker.jpg'
2022-12-05 09:22:01,526 - 127.0.0.1 - - [05/Dec/2022 09:22:01] "[35m[1mGET /convert?filename=docker HTTP/1.1[0m" 500 -
2022-12-05 09:22:50,811 -  * Running on http://127.0.0.1:5000/ (Press CTRL+C to quit)
2022-12-05 09:23:17,269 -  * Running on http://127.0.0.1:5000/ (Press CTRL+C to quit)
2022-12-05 09:23:23,391 - Converting docker
2022-12-05 09:23:23,392 - Exception on /convert [GET]
Traceback (most recent call last):
  File "C:\Users\eitan\AppData\Local\Packages\PythonSoftwareFoundation.Python.3.9_qbz5n2kfra8p0\LocalCache\local-packages\Python39\site-packages\flask\app.py", line 2447, in wsgi_app
    response = self.full_dispatch_request()
  File "C:\Users\eitan\AppData\Local\Packages\PythonSoftwareFoundation.Python.3.9_qbz5n2kfra8p0\LocalCache\local-packages\Python39\site-packages\flask\app.py", line 1952, in full_dispatch_request
    rv = self.handle_user_exception(e)
  File "C:\Users\eitan\AppData\Local\Packages\PythonSoftwareFoundation.Python.3.9_qbz5n2kfra8p0\LocalCache\local-packages\Python39\site-packages\flask\app.py", line 1821, in handle_user_exception
    reraise(exc_type, exc_value, tb)
  File "C:\Users\eitan\AppData\Local\Packages\PythonSoftwareFoundation.Python.3.9_qbz5n2kfra8p0\LocalCache\local-packages\Python39\site-packages\flask\_compat.py", line 39, in reraise
    raise value
  File "C:\Users\eitan\AppData\Local\Packages\PythonSoftwareFoundation.Python.3.9_qbz5n2kfra8p0\LocalCache\local-packages\Python39\site-packages\flask\app.py", line 1950, in full_dispatch_request
    rv = self.dispatch_request()
  File "C:\Users\eitan\AppData\Local\Packages\PythonSoftwareFoundation.Python.3.9_qbz5n2kfra8p0\LocalCache\local-packages\Python39\site-packages\flask\app.py", line 1936, in dispatch_request
    return self.view_functions[rule.endpoint](**req.view_args)
  File "c:\Users\eitan\projects\img2pdf\main.py", line 11, in hello_world
    return convert(filename)
  File "c:\Users\eitan\projects\img2pdf\lib\utils.py", line 14, in convert
    image = Image.open(img_path)
  File "C:\Users\eitan\AppData\Local\Packages\PythonSoftwareFoundation.Python.3.9_qbz5n2kfra8p0\LocalCache\local-packages\Python39\site-packages\PIL\Image.py", line 3131, in open
    fp = builtins.open(filename, "rb")
FileNotFoundError: [Errno 2] No such file or directory: 'c:\\Users\\eitan\\projects\\img2pdfdocker.jpg'
2022-12-05 09:23:23,394 - 127.0.0.1 - - [05/Dec/2022 09:23:23] "[35m[1mGET /convert?filename=docker HTTP/1.1[0m" 500 -
2022-12-05 09:23:33,748 - Converting docker
2022-12-05 09:23:33,749 - Exception on /convert [GET]
Traceback (most recent call last):
  File "C:\Users\eitan\AppData\Local\Packages\PythonSoftwareFoundation.Python.3.9_qbz5n2kfra8p0\LocalCache\local-packages\Python39\site-packages\flask\app.py", line 2447, in wsgi_app
    response = self.full_dispatch_request()
  File "C:\Users\eitan\AppData\Local\Packages\PythonSoftwareFoundation.Python.3.9_qbz5n2kfra8p0\LocalCache\local-packages\Python39\site-packages\flask\app.py", line 1952, in full_dispatch_request
    rv = self.handle_user_exception(e)
  File "C:\Users\eitan\AppData\Local\Packages\PythonSoftwareFoundation.Python.3.9_qbz5n2kfra8p0\LocalCache\local-packages\Python39\site-packages\flask\app.py", line 1821, in handle_user_exception
    reraise(exc_type, exc_value, tb)
  File "C:\Users\eitan\AppData\Local\Packages\PythonSoftwareFoundation.Python.3.9_qbz5n2kfra8p0\LocalCache\local-packages\Python39\site-packages\flask\_compat.py", line 39, in reraise
    raise value
  File "C:\Users\eitan\AppData\Local\Packages\PythonSoftwareFoundation.Python.3.9_qbz5n2kfra8p0\LocalCache\local-packages\Python39\site-packages\flask\app.py", line 1950, in full_dispatch_request
    rv = self.dispatch_request()
  File "C:\Users\eitan\AppData\Local\Packages\PythonSoftwareFoundation.Python.3.9_qbz5n2kfra8p0\LocalCache\local-packages\Python39\site-packages\flask\app.py", line 1936, in dispatch_request
    return self.view_functions[rule.endpoint](**req.view_args)
  File "c:\Users\eitan\projects\img2pdf\main.py", line 11, in hello_world
    return convert(filename)
  File "c:\Users\eitan\projects\img2pdf\lib\utils.py", line 14, in convert
    image = Image.open(img_path)
  File "C:\Users\eitan\AppData\Local\Packages\PythonSoftwareFoundation.Python.3.9_qbz5n2kfra8p0\LocalCache\local-packages\Python39\site-packages\PIL\Image.py", line 3131, in open
    fp = builtins.open(filename, "rb")
FileNotFoundError: [Errno 2] No such file or directory: 'c:\\Users\\eitan\\projects\\img2pdfdocker.jpg'
2022-12-05 09:23:33,749 - 127.0.0.1 - - [05/Dec/2022 09:23:33] "[35m[1mGET /convert?filename=docker HTTP/1.1[0m" 500 -
2022-12-05 09:24:18,643 -  * Running on http://127.0.0.1:5000/ (Press CTRL+C to quit)
2022-12-05 09:24:21,161 - Converting docker
2022-12-05 09:24:21,161 - Exception on /convert [GET]
Traceback (most recent call last):
  File "C:\Users\eitan\AppData\Local\Packages\PythonSoftwareFoundation.Python.3.9_qbz5n2kfra8p0\LocalCache\local-packages\Python39\site-packages\flask\app.py", line 2447, in wsgi_app
    response = self.full_dispatch_request()
  File "C:\Users\eitan\AppData\Local\Packages\PythonSoftwareFoundation.Python.3.9_qbz5n2kfra8p0\LocalCache\local-packages\Python39\site-packages\flask\app.py", line 1952, in full_dispatch_request
    rv = self.handle_user_exception(e)
  File "C:\Users\eitan\AppData\Local\Packages\PythonSoftwareFoundation.Python.3.9_qbz5n2kfra8p0\LocalCache\local-packages\Python39\site-packages\flask\app.py", line 1821, in handle_user_exception
    reraise(exc_type, exc_value, tb)
  File "C:\Users\eitan\AppData\Local\Packages\PythonSoftwareFoundation.Python.3.9_qbz5n2kfra8p0\LocalCache\local-packages\Python39\site-packages\flask\_compat.py", line 39, in reraise
    raise value
  File "C:\Users\eitan\AppData\Local\Packages\PythonSoftwareFoundation.Python.3.9_qbz5n2kfra8p0\LocalCache\local-packages\Python39\site-packages\flask\app.py", line 1950, in full_dispatch_request
    rv = self.dispatch_request()
  File "C:\Users\eitan\AppData\Local\Packages\PythonSoftwareFoundation.Python.3.9_qbz5n2kfra8p0\LocalCache\local-packages\Python39\site-packages\flask\app.py", line 1936, in dispatch_request
    return self.view_functions[rule.endpoint](**req.view_args)
  File "c:\Users\eitan\projects\img2pdf\main.py", line 11, in hello_world
    return convert(filename)
  File "c:\Users\eitan\projects\img2pdf\lib\utils.py", line 14, in convert
    image = Image.open(img_path)
  File "C:\Users\eitan\AppData\Local\Packages\PythonSoftwareFoundation.Python.3.9_qbz5n2kfra8p0\LocalCache\local-packages\Python39\site-packages\PIL\Image.py", line 3131, in open
    fp = builtins.open(filename, "rb")
FileNotFoundError: [Errno 2] No such file or directory: 'c:\\Users\\eitan\\projects\\img2pdfdocker.jpg'
2022-12-05 09:24:21,166 - 127.0.0.1 - - [05/Dec/2022 09:24:21] "[35m[1mGET /convert?filename=docker HTTP/1.1[0m" 500 -
2022-12-05 09:24:33,995 - Converting docker
2022-12-05 09:24:33,996 - Exception on /convert [GET]
Traceback (most recent call last):
  File "C:\Users\eitan\AppData\Local\Packages\PythonSoftwareFoundation.Python.3.9_qbz5n2kfra8p0\LocalCache\local-packages\Python39\site-packages\flask\app.py", line 2447, in wsgi_app
    response = self.full_dispatch_request()
  File "C:\Users\eitan\AppData\Local\Packages\PythonSoftwareFoundation.Python.3.9_qbz5n2kfra8p0\LocalCache\local-packages\Python39\site-packages\flask\app.py", line 1952, in full_dispatch_request
    rv = self.handle_user_exception(e)
  File "C:\Users\eitan\AppData\Local\Packages\PythonSoftwareFoundation.Python.3.9_qbz5n2kfra8p0\LocalCache\local-packages\Python39\site-packages\flask\app.py", line 1821, in handle_user_exception
    reraise(exc_type, exc_value, tb)
  File "C:\Users\eitan\AppData\Local\Packages\PythonSoftwareFoundation.Python.3.9_qbz5n2kfra8p0\LocalCache\local-packages\Python39\site-packages\flask\_compat.py", line 39, in reraise
    raise value
  File "C:\Users\eitan\AppData\Local\Packages\PythonSoftwareFoundation.Python.3.9_qbz5n2kfra8p0\LocalCache\local-packages\Python39\site-packages\flask\app.py", line 1950, in full_dispatch_request
    rv = self.dispatch_request()
  File "C:\Users\eitan\AppData\Local\Packages\PythonSoftwareFoundation.Python.3.9_qbz5n2kfra8p0\LocalCache\local-packages\Python39\site-packages\flask\app.py", line 1936, in dispatch_request
    return self.view_functions[rule.endpoint](**req.view_args)
  File "c:\Users\eitan\projects\img2pdf\main.py", line 11, in hello_world
    return convert(filename)
  File "c:\Users\eitan\projects\img2pdf\lib\utils.py", line 14, in convert
    image = Image.open(img_path)
  File "C:\Users\eitan\AppData\Local\Packages\PythonSoftwareFoundation.Python.3.9_qbz5n2kfra8p0\LocalCache\local-packages\Python39\site-packages\PIL\Image.py", line 3131, in open
    fp = builtins.open(filename, "rb")
FileNotFoundError: [Errno 2] No such file or directory: 'c:\\Users\\eitan\\projects\\img2pdfdocker.jpg'
2022-12-05 09:24:33,996 - 127.0.0.1 - - [05/Dec/2022 09:24:33] "[35m[1mGET /convert?filename=docker HTTP/1.1[0m" 500 -
2022-12-05 09:24:48,050 - Exception on /test [GET]
Traceback (most recent call last):
  File "C:\Users\eitan\AppData\Local\Packages\PythonSoftwareFoundation.Python.3.9_qbz5n2kfra8p0\LocalCache\local-packages\Python39\site-packages\flask\app.py", line 2447, in wsgi_app
    response = self.full_dispatch_request()
  File "C:\Users\eitan\AppData\Local\Packages\PythonSoftwareFoundation.Python.3.9_qbz5n2kfra8p0\LocalCache\local-packages\Python39\site-packages\flask\app.py", line 1953, in full_dispatch_request
    return self.finalize_request(rv)
  File "C:\Users\eitan\AppData\Local\Packages\PythonSoftwareFoundation.Python.3.9_qbz5n2kfra8p0\LocalCache\local-packages\Python39\site-packages\flask\app.py", line 1968, in finalize_request
    response = self.make_response(rv)
  File "C:\Users\eitan\AppData\Local\Packages\PythonSoftwareFoundation.Python.3.9_qbz5n2kfra8p0\LocalCache\local-packages\Python39\site-packages\flask\app.py", line 2097, in make_response
    raise TypeError(
TypeError: The view function did not return a valid response. The function either returned None or ended without a return statement.
2022-12-05 09:24:48,050 - 127.0.0.1 - - [05/Dec/2022 09:24:48] "[35m[1mGET /test HTTP/1.1[0m" 500 -
2022-12-05 09:24:49,034 - Exception on /test [GET]
Traceback (most recent call last):
  File "C:\Users\eitan\AppData\Local\Packages\PythonSoftwareFoundation.Python.3.9_qbz5n2kfra8p0\LocalCache\local-packages\Python39\site-packages\flask\app.py", line 2447, in wsgi_app
    response = self.full_dispatch_request()
  File "C:\Users\eitan\AppData\Local\Packages\PythonSoftwareFoundation.Python.3.9_qbz5n2kfra8p0\LocalCache\local-packages\Python39\site-packages\flask\app.py", line 1953, in full_dispatch_request
    return self.finalize_request(rv)
  File "C:\Users\eitan\AppData\Local\Packages\PythonSoftwareFoundation.Python.3.9_qbz5n2kfra8p0\LocalCache\local-packages\Python39\site-packages\flask\app.py", line 1968, in finalize_request
    response = self.make_response(rv)
  File "C:\Users\eitan\AppData\Local\Packages\PythonSoftwareFoundation.Python.3.9_qbz5n2kfra8p0\LocalCache\local-packages\Python39\site-packages\flask\app.py", line 2097, in make_response
    raise TypeError(
TypeError: The view function did not return a valid response. The function either returned None or ended without a return statement.
2022-12-05 09:24:49,034 - 127.0.0.1 - - [05/Dec/2022 09:24:49] "[35m[1mGET /test HTTP/1.1[0m" 500 -
2022-12-05 09:24:49,650 - Exception on /test [GET]
Traceback (most recent call last):
  File "C:\Users\eitan\AppData\Local\Packages\PythonSoftwareFoundation.Python.3.9_qbz5n2kfra8p0\LocalCache\local-packages\Python39\site-packages\flask\app.py", line 2447, in wsgi_app
    response = self.full_dispatch_request()
  File "C:\Users\eitan\AppData\Local\Packages\PythonSoftwareFoundation.Python.3.9_qbz5n2kfra8p0\LocalCache\local-packages\Python39\site-packages\flask\app.py", line 1953, in full_dispatch_request
    return self.finalize_request(rv)
  File "C:\Users\eitan\AppData\Local\Packages\PythonSoftwareFoundation.Python.3.9_qbz5n2kfra8p0\LocalCache\local-packages\Python39\site-packages\flask\app.py", line 1968, in finalize_request
    response = self.make_response(rv)
  File "C:\Users\eitan\AppData\Local\Packages\PythonSoftwareFoundation.Python.3.9_qbz5n2kfra8p0\LocalCache\local-packages\Python39\site-packages\flask\app.py", line 2097, in make_response
    raise TypeError(
TypeError: The view function did not return a valid response. The function either returned None or ended without a return statement.
2022-12-05 09:24:49,651 - 127.0.0.1 - - [05/Dec/2022 09:24:49] "[35m[1mGET /test HTTP/1.1[0m" 500 -
2022-12-05 09:25:05,403 -  * Running on http://127.0.0.1:5000/ (Press CTRL+C to quit)
2022-12-05 09:25:06,383 - 127.0.0.1 - - [05/Dec/2022 09:25:06] "[37mGET /test HTTP/1.1[0m" 200 -
2022-12-05 09:25:09,580 - Converting docker
2022-12-05 09:25:09,581 - Exception on /convert [GET]
Traceback (most recent call last):
  File "C:\Users\eitan\AppData\Local\Packages\PythonSoftwareFoundation.Python.3.9_qbz5n2kfra8p0\LocalCache\local-packages\Python39\site-packages\flask\app.py", line 2447, in wsgi_app
    response = self.full_dispatch_request()
  File "C:\Users\eitan\AppData\Local\Packages\PythonSoftwareFoundation.Python.3.9_qbz5n2kfra8p0\LocalCache\local-packages\Python39\site-packages\flask\app.py", line 1952, in full_dispatch_request
    rv = self.handle_user_exception(e)
  File "C:\Users\eitan\AppData\Local\Packages\PythonSoftwareFoundation.Python.3.9_qbz5n2kfra8p0\LocalCache\local-packages\Python39\site-packages\flask\app.py", line 1821, in handle_user_exception
    reraise(exc_type, exc_value, tb)
  File "C:\Users\eitan\AppData\Local\Packages\PythonSoftwareFoundation.Python.3.9_qbz5n2kfra8p0\LocalCache\local-packages\Python39\site-packages\flask\_compat.py", line 39, in reraise
    raise value
  File "C:\Users\eitan\AppData\Local\Packages\PythonSoftwareFoundation.Python.3.9_qbz5n2kfra8p0\LocalCache\local-packages\Python39\site-packages\flask\app.py", line 1950, in full_dispatch_request
    rv = self.dispatch_request()
  File "C:\Users\eitan\AppData\Local\Packages\PythonSoftwareFoundation.Python.3.9_qbz5n2kfra8p0\LocalCache\local-packages\Python39\site-packages\flask\app.py", line 1936, in dispatch_request
    return self.view_functions[rule.endpoint](**req.view_args)
  File "c:\Users\eitan\projects\img2pdf\main.py", line 11, in hello_world
    return convert(filename)
  File "c:\Users\eitan\projects\img2pdf\lib\utils.py", line 14, in convert
    image = Image.open(img_path)
  File "C:\Users\eitan\AppData\Local\Packages\PythonSoftwareFoundation.Python.3.9_qbz5n2kfra8p0\LocalCache\local-packages\Python39\site-packages\PIL\Image.py", line 3131, in open
    fp = builtins.open(filename, "rb")
FileNotFoundError: [Errno 2] No such file or directory: 'c:\\Users\\eitan\\projects\\img2pdfdocker.jpg'
2022-12-05 09:25:09,583 - 127.0.0.1 - - [05/Dec/2022 09:25:09] "[35m[1mGET /convert?filename=docker HTTP/1.1[0m" 500 -
2022-12-05 09:28:13,300 - Converting docker
2022-12-05 09:28:13,301 - Exception on /convert [GET]
Traceback (most recent call last):
  File "C:\Users\eitan\AppData\Local\Packages\PythonSoftwareFoundation.Python.3.9_qbz5n2kfra8p0\LocalCache\local-packages\Python39\site-packages\flask\app.py", line 2447, in wsgi_app
    response = self.full_dispatch_request()
  File "C:\Users\eitan\AppData\Local\Packages\PythonSoftwareFoundation.Python.3.9_qbz5n2kfra8p0\LocalCache\local-packages\Python39\site-packages\flask\app.py", line 1952, in full_dispatch_request
    rv = self.handle_user_exception(e)
  File "C:\Users\eitan\AppData\Local\Packages\PythonSoftwareFoundation.Python.3.9_qbz5n2kfra8p0\LocalCache\local-packages\Python39\site-packages\flask\app.py", line 1821, in handle_user_exception
    reraise(exc_type, exc_value, tb)
  File "C:\Users\eitan\AppData\Local\Packages\PythonSoftwareFoundation.Python.3.9_qbz5n2kfra8p0\LocalCache\local-packages\Python39\site-packages\flask\_compat.py", line 39, in reraise
    raise value
  File "C:\Users\eitan\AppData\Local\Packages\PythonSoftwareFoundation.Python.3.9_qbz5n2kfra8p0\LocalCache\local-packages\Python39\site-packages\flask\app.py", line 1950, in full_dispatch_request
    rv = self.dispatch_request()
  File "C:\Users\eitan\AppData\Local\Packages\PythonSoftwareFoundation.Python.3.9_qbz5n2kfra8p0\LocalCache\local-packages\Python39\site-packages\flask\app.py", line 1936, in dispatch_request
    return self.view_functions[rule.endpoint](**req.view_args)
  File "c:\Users\eitan\projects\img2pdf\main.py", line 11, in hello_world
    return convert(filename)
  File "c:\Users\eitan\projects\img2pdf\lib\utils.py", line 14, in convert
    image = Image.open(img_path)
  File "C:\Users\eitan\AppData\Local\Packages\PythonSoftwareFoundation.Python.3.9_qbz5n2kfra8p0\LocalCache\local-packages\Python39\site-packages\PIL\Image.py", line 3131, in open
    fp = builtins.open(filename, "rb")
FileNotFoundError: [Errno 2] No such file or directory: 'c:\\Users\\eitan\\projects\\img2pdfdocker.jpg'
2022-12-05 09:28:13,304 - 127.0.0.1 - - [05/Dec/2022 09:28:13] "[35m[1mGET /convert?filename=docker HTTP/1.1[0m" 500 -
2022-12-05 09:28:50,092 -  * Running on http://127.0.0.1:5000/ (Press CTRL+C to quit)
2022-12-05 09:28:51,819 - Converting docker
2022-12-05 09:28:51,820 - Exception on /convert [GET]
Traceback (most recent call last):
  File "C:\Users\eitan\AppData\Local\Packages\PythonSoftwareFoundation.Python.3.9_qbz5n2kfra8p0\LocalCache\local-packages\Python39\site-packages\flask\app.py", line 2447, in wsgi_app
    response = self.full_dispatch_request()
  File "C:\Users\eitan\AppData\Local\Packages\PythonSoftwareFoundation.Python.3.9_qbz5n2kfra8p0\LocalCache\local-packages\Python39\site-packages\flask\app.py", line 1952, in full_dispatch_request
    rv = self.handle_user_exception(e)
  File "C:\Users\eitan\AppData\Local\Packages\PythonSoftwareFoundation.Python.3.9_qbz5n2kfra8p0\LocalCache\local-packages\Python39\site-packages\flask\app.py", line 1821, in handle_user_exception
    reraise(exc_type, exc_value, tb)
  File "C:\Users\eitan\AppData\Local\Packages\PythonSoftwareFoundation.Python.3.9_qbz5n2kfra8p0\LocalCache\local-packages\Python39\site-packages\flask\_compat.py", line 39, in reraise
    raise value
  File "C:\Users\eitan\AppData\Local\Packages\PythonSoftwareFoundation.Python.3.9_qbz5n2kfra8p0\LocalCache\local-packages\Python39\site-packages\flask\app.py", line 1950, in full_dispatch_request
    rv = self.dispatch_request()
  File "C:\Users\eitan\AppData\Local\Packages\PythonSoftwareFoundation.Python.3.9_qbz5n2kfra8p0\LocalCache\local-packages\Python39\site-packages\flask\app.py", line 1936, in dispatch_request
    return self.view_functions[rule.endpoint](**req.view_args)
  File "c:\Users\eitan\projects\img2pdf\main.py", line 11, in hello_world
    return convert(filename)
  File "c:\Users\eitan\projects\img2pdf\lib\utils.py", line 15, in convert
    image = Image.open(img_path)
  File "C:\Users\eitan\AppData\Local\Packages\PythonSoftwareFoundation.Python.3.9_qbz5n2kfra8p0\LocalCache\local-packages\Python39\site-packages\PIL\Image.py", line 3131, in open
    fp = builtins.open(filename, "rb")
FileNotFoundError: [Errno 2] No such file or directory: 'c:\\Users\\eitan\\projects\\img2pdfdocker.jpg'
2022-12-05 09:28:51,823 - 127.0.0.1 - - [05/Dec/2022 09:28:51] "[35m[1mGET /convert?filename=docker HTTP/1.1[0m" 500 -
2022-12-05 09:31:33,029 -  * Running on http://127.0.0.1:5000/ (Press CTRL+C to quit)
2022-12-05 09:31:35,287 - Converting docker
2022-12-05 09:31:35,312 - 127.0.0.1 - - [05/Dec/2022 09:31:35] "[37mGET /convert?filename=docker HTTP/1.1[0m" 200 -
2022-12-05 09:33:47,490 -  * Running on http://127.0.0.1:5000/ (Press CTRL+C to quit)
2022-12-05 09:33:50,414 - Converting docker
2022-12-05 09:33:50,414 - Exception on /convert [GET]
Traceback (most recent call last):
  File "C:\Users\eitan\AppData\Local\Packages\PythonSoftwareFoundation.Python.3.9_qbz5n2kfra8p0\LocalCache\local-packages\Python39\site-packages\flask\app.py", line 2447, in wsgi_app
    response = self.full_dispatch_request()
  File "C:\Users\eitan\AppData\Local\Packages\PythonSoftwareFoundation.Python.3.9_qbz5n2kfra8p0\LocalCache\local-packages\Python39\site-packages\flask\app.py", line 1952, in full_dispatch_request
    rv = self.handle_user_exception(e)
  File "C:\Users\eitan\AppData\Local\Packages\PythonSoftwareFoundation.Python.3.9_qbz5n2kfra8p0\LocalCache\local-packages\Python39\site-packages\flask\app.py", line 1821, in handle_user_exception
    reraise(exc_type, exc_value, tb)
  File "C:\Users\eitan\AppData\Local\Packages\PythonSoftwareFoundation.Python.3.9_qbz5n2kfra8p0\LocalCache\local-packages\Python39\site-packages\flask\_compat.py", line 39, in reraise
    raise value
  File "C:\Users\eitan\AppData\Local\Packages\PythonSoftwareFoundation.Python.3.9_qbz5n2kfra8p0\LocalCache\local-packages\Python39\site-packages\flask\app.py", line 1950, in full_dispatch_request
    rv = self.dispatch_request()
  File "C:\Users\eitan\AppData\Local\Packages\PythonSoftwareFoundation.Python.3.9_qbz5n2kfra8p0\LocalCache\local-packages\Python39\site-packages\flask\app.py", line 1936, in dispatch_request
    return self.view_functions[rule.endpoint](**req.view_args)
  File "c:\Users\eitan\projects\img2pdf\main.py", line 11, in hello_world
    return convert(filename)
  File "c:\Users\eitan\projects\img2pdf\lib\utils.py", line 15, in convert
    pdf_path = pfdPath+filename+".pdf"
NameError: name 'pfdPath' is not defined
2022-12-05 09:33:50,416 - 127.0.0.1 - - [05/Dec/2022 09:33:50] "[35m[1mGET /convert?filename=docker HTTP/1.1[0m" 500 -
2022-12-05 09:34:14,352 -  * Running on http://127.0.0.1:5000/ (Press CTRL+C to quit)
2022-12-05 09:34:15,528 - Converting docker
2022-12-05 09:34:15,556 - 127.0.0.1 - - [05/Dec/2022 09:34:15] "[37mGET /convert?filename=docker HTTP/1.1[0m" 200 -
2022-12-05 09:36:50,500 -  * Running on http://127.0.0.1:5000/ (Press CTRL+C to quit)
2022-12-05 09:36:52,505 - Exception on /convert [GET]
Traceback (most recent call last):
  File "C:\Users\eitan\AppData\Local\Packages\PythonSoftwareFoundation.Python.3.9_qbz5n2kfra8p0\LocalCache\local-packages\Python39\site-packages\flask\app.py", line 2447, in wsgi_app
    response = self.full_dispatch_request()
  File "C:\Users\eitan\AppData\Local\Packages\PythonSoftwareFoundation.Python.3.9_qbz5n2kfra8p0\LocalCache\local-packages\Python39\site-packages\flask\app.py", line 1952, in full_dispatch_request
    rv = self.handle_user_exception(e)
  File "C:\Users\eitan\AppData\Local\Packages\PythonSoftwareFoundation.Python.3.9_qbz5n2kfra8p0\LocalCache\local-packages\Python39\site-packages\flask\app.py", line 1821, in handle_user_exception
    reraise(exc_type, exc_value, tb)
  File "C:\Users\eitan\AppData\Local\Packages\PythonSoftwareFoundation.Python.3.9_qbz5n2kfra8p0\LocalCache\local-packages\Python39\site-packages\flask\_compat.py", line 39, in reraise
    raise value
  File "C:\Users\eitan\AppData\Local\Packages\PythonSoftwareFoundation.Python.3.9_qbz5n2kfra8p0\LocalCache\local-packages\Python39\site-packages\flask\app.py", line 1950, in full_dispatch_request
    rv = self.dispatch_request()
  File "C:\Users\eitan\AppData\Local\Packages\PythonSoftwareFoundation.Python.3.9_qbz5n2kfra8p0\LocalCache\local-packages\Python39\site-packages\flask\app.py", line 1936, in dispatch_request
    return self.view_functions[rule.endpoint](**req.view_args)
  File "c:\Users\eitan\projects\img2pdf\main.py", line 11, in hello_world
    return convert(filename)
  File "c:\Users\eitan\projects\img2pdf\lib\utils.py", line 13, in convert
    logging.info("Converting "+jpgPath+filename+" to "+pdf_path)
UnboundLocalError: local variable 'pdf_path' referenced before assignment
2022-12-05 09:36:52,517 - 127.0.0.1 - - [05/Dec/2022 09:36:52] "[35m[1mGET /convert?filename=docker HTTP/1.1[0m" 500 -
2022-12-05 09:37:27,986 -  * Running on http://127.0.0.1:5000/ (Press CTRL+C to quit)
2022-12-05 09:37:29,033 - Converting c:\Users\eitan\projects\img2pdf\docker to c:\Users\eitan\projects\img2pdf\
2022-12-05 09:37:29,097 - 127.0.0.1 - - [05/Dec/2022 09:37:29] "[37mGET /convert?filename=docker HTTP/1.1[0m" 200 -
